Workbook

Sheet Coretax
A1: Nomor | B1: Nama Lengkap | C1: NIP | D1: Pangkat | E1: Unit | F1: Bagian/Bidang/Sub Unsur | G1: LOGIN_PORTAL (SUDAH PERNAH LOG IN) | H1: SUDAH KODE OTORISASI / BELUM | I1: Bukti Registrasi
A2: 1 | B2: Himawan Indarjono | C2: 197003131989121001 | D2: IV/b | F2: Bagian Umum | G2: =VLOOKUP(C2,'Zip Pajak'!$A$2:$E$1280,4,FALSE) -> YA | H2: =VLOOKUP(C2,'Zip Pajak'!$A$1:$E$1280,5,FALSE) -> YA | I2: =VLOOKUP(C2,'Olah Data'!$B$2:$D$81,3,FALSE) -> https://kemenkeu-my.sharepoint.com/personal/izdhihar_rayhanah_kemenkeu_go_id/Documents/Apps/Microsoft%20Forms/Monitoring%20Aktivasi%20Akun%20WP%20dan%20Registrasi%20Kode%20Ot/Question/Image%2008-12-25%20at%2011.23_Himawan%20Indarjono,%20S.jpeg
A3: 2 | B3: Ahmad Saifuddin Zuhri | C3: 197911102001121001 | D3: IV/a | E3: Subbagian Kepegawaian | F3: Bagian Umum | G3: =VLOOKUP(C3,'Zip Pajak'!$A$2:$E$1280,4,FALSE) -> YA | H3: =VLOOKUP(C3,'Zip Pajak'!$A$1:$E$1280,5,FALSE) -> YA | I3: =VLOOKUP(C3,'Olah Data'!$B$2:$D$81,3,FALSE) -> https://kemenkeu-my.sharepoint.com/personal/izdhihar_rayhanah_kemenkeu_go_id/Documents/Apps/Microsoft%20Forms/Monitoring%20Aktivasi%20Akun%20WP%20dan%20Registrasi%20Kode%20Ot/Question/Bukti%20aktivasi%20coretax_Ahmad%20Saifuddin%20Zuhr.png
A4: 3 | B4: Sapta Pinardi | C4: 197504281996021001 | D4: IV/a | E4: Subbagian Rumah Tangga | F4: Bagian Umum | G4: =VLOOKUP(C4,'Zip Pajak'!$A$2:$E$1280,4,FALSE) -> YA | H4: =VLOOKUP(C4,'Zip Pajak'!$A$1:$E$1280,5,FALSE) -> YA | I4: =VLOOKUP(C4,'Olah Data'!$B$2:$D$81,3,FALSE) -> https://kemenkeu-my.sharepoint.com/personal/izdhihar_rayhanah_kemenkeu_go_id/Documents/Apps/Microsoft%20Forms/Monitoring%20Aktivasi%20Akun%20WP%20dan%20Registrasi%20Kode%20Ot/Question/SS%20NIE_Sapta%20Pinardi,%20S.E.,.png
A5: 4 | B5: Angga Girasandi Argadinata | C5: 197611232002121001 | D5: III/d | E5: Subbagian Tata Usaha dan Keuangan | F5: Bagian Umum | G5: =VLOOKUP(C5,'Zip Pajak'!$A$2:$E$1280,4,FALSE) -> YA | H5: =VLOOKUP(C5,'Zip Pajak'!$A$1:$E$1280,5,FALSE) -> YA | I5: =VLOOKUP(C5,'Olah Data'!$B$2:$D$81,3,FALSE) -> #N/A
A6: 5 | B6: Fenti Fitria Lestari | C6: 198111182003122007 | D6: III/d | E6: Subbagian Tata Usaha dan Keuangan | F6: Bagian Umum | G6: =VLOOKUP(C6,'Zip Pajak'!$A$2:$E$1280,4,FALSE) -> YA | H6: =VLOOKUP(C6,'Zip Pajak'!$A$1:$E$1280,5,FALSE) -> YA | I6: =VLOOKUP(C6,'Olah Data'!$B$2:$D$81,3,FALSE) -> https://kemenkeu-my.sharepoint.com/personal/izdhihar_rayhanah_kemenkeu_go_id/Documents/Apps/Microsoft%20Forms/Monitoring%20Aktivasi%20Akun%20WP%20dan%20Registrasi%20Kode%20Ot/Question/Bukti%20Cortex%20Fenti_Fenti%20Fitria%20Lestari.jpeg
A7: 6 | B7: Bambang Subeqi | C7: 197706241997031002 | D7: III/c | E7: Subbagian Kepegawaian | F7: Bagian Umum | G7: =VLOOKUP(C7,'Zip Pajak'!$A$2:$E$1280,4,FALSE) -> TIDAK | H7: BELUM KODE OTORISASI | I7: =VLOOKUP(C7,'Olah Data'!$B$2:$D$81,3,FALSE) -> #N/A
A8: 7 | B8: Dwi Sriwahyuni | C8: 199003012012102002 | D8: III/b | E8: Subbagian Tata Usaha dan Keuangan | F8: Bagian Umum | G8: =VLOOKUP(C8,'Zip Pajak'!$A$2:$E$1280,4,FALSE) -> YA | H8: =VLOOKUP(C8,'Zip Pajak'!$A$1:$E$1280,5,FALSE) -> YA | I8: =VLOOKUP(C8,'Olah Data'!$B$2:$D$81,3,FALSE) -> https://kemenkeu-my.sharepoint.com/personal/izdhihar_rayhanah_kemenkeu_go_id/Documents/Apps/Microsoft%20Forms/Monitoring%20Aktivasi%20Akun%20WP%20dan%20Registrasi%20Kode%20Ot/Question/A_01-DOC010-DIGITAL_CERTIFICATE_ISSUANCE_LETT_Dwi%20Sriwahyuni.pdf
A9: 8 | B9: Meriana Dwi Puspita | C9: 199005232012102001 | D9: III/b | E9: Subbagian Rumah Tangga | F9: Bagian Umum | G9: =VLOOKUP(C9,'Zip Pajak'!$A$2:$E$1280,4,FALSE) -> YA | H9: =VLOOKUP(C9,'Zip Pajak'!$A$1:$E$1280,5,FALSE) -> YA | I9: =VLOOKUP(C9,'Olah Data'!$B$2:$D$81,3,FALSE) -> https://kemenkeu-my.sharepoint.com/personal/izdhihar_rayhanah_kemenkeu_go_id/Documents/Apps/Microsoft%20Forms/Monitoring%20Aktivasi%20Akun%20WP%20dan%20Registrasi%20Kode%20Ot/Question/A_01-DOC010-DIGITAL_CERTIFICATE_ISSUANCE_LETT_Meriana%20Dwi%20Puspita.pdf
A10: 9 | B10: Freesia Putri Erwana | C10: 199407242015022002 | D10: III/a | E10: Subbagian Tata Usaha dan Keuangan | F10: Bagian Umum | G10: =VLOOKUP(C10,'Zip Pajak'!$A$2:$E$1280,4,FALSE) -> YA | H10: =VLOOKUP(C10,'Zip Pajak'!$A$1:$E$1280,5,FALSE) -> YA | I10: =VLOOKUP(C10,'Olah Data'!$B$2:$D$81,3,FALSE) -> https://kemenkeu-my.sharepoint.com/personal/izdhihar_rayhanah_kemenkeu_go_id/Documents/Apps/Microsoft%20Forms/Monitoring%20Aktivasi%20Akun%20WP%20dan%20Registrasi%20Kode%20Ot/Question/Freesia%20Putri_FREESIA%20PUTRI%20ERWANA.png
A11: 10 | B11: Mudho Cahyo Utomo | C11: 198707052006021002 | D11: III/a | E11: Subbagian Rumah Tangga | F11: Bagian Umum | G11: =VLOOKUP(C11,'Zip Pajak'!$A$2:$E$1280,4,FALSE) -> YA | H11: =VLOOKUP(C11,'Zip Pajak'!$A$1:$E$1280,5,FALSE) -> YA | I11: =VLOOKUP(C11,'Olah Data'!$B$2:$D$81,3,FALSE) -> #N/A
A12: 11 | B12: Prima Ageng Nugraha | C12: 199504262015021003 | D12: III/a | E12: Subbagian Kepegawaian | F12: Bagian Umum | G12: =VLOOKUP(C12,'Zip Pajak'!$A$2:$E$1280,4,FALSE) -> YA | H12: =VLOOKUP(C12,'Zip Pajak'!$A$1:$E$1280,5,FALSE) -> YA | I12: =VLOOKUP(C12,'Olah Data'!$B$2:$D$81,3,FALSE) -> #N/A
A13: 12 | B13: Bella Atria | C13: 199701312015122001 | D13: II/d | E13: Subbagian Kepegawaian | F13: Bagian Umum | G13: =VLOOKUP(C13,'Zip Pajak'!$A$2:$E$1280,4,FALSE) -> YA | H13: =VLOOKUP(C13,'Zip Pajak'!$A$1:$E$1280,5,FALSE) -> YA | I13: =VLOOKUP(C13,'Olah Data'!$B$2:$D$81,3,FALSE) -> https://kemenkeu-my.sharepoint.com/personal/izdhihar_rayhanah_kemenkeu_go_id/Documents/Apps/Microsoft%20Forms/Monitoring%20Aktivasi%20Akun%20WP%20dan%20Registrasi%20Kode%20Ot/Question/Bukti%20kode%20otorisasi_Bella%20Atria.png
A14: 13 | B14: Dimas Ananto Witjaksono | C14: 199809032019121002 | D14: II/d | E14: Subbagian Tata Usaha dan Keuangan | F14: Bagian Umum | G14: =VLOOKUP(C14,'Zip Pajak'!$A$2:$E$1280,4,FALSE) -> YA | H14: =VLOOKUP(C14,'Zip Pajak'!$A$1:$E$1280,5,FALSE) -> YA | I14: =VLOOKUP(C14,'Olah Data'!$B$2:$D$81,3,FALSE) -> #N/A
A15: 14 | B15: Duana Jerry Pahlawan | C15: 199611102018121002 | D15: II/d | E15: Subbagian Kepegawaian | F15: Bagian Umum | G15: =VLOOKUP(C15,'Zip Pajak'!$A$2:$E$1280,4,FALSE) -> YA | H15: =VLOOKUP(C15,'Zip Pajak'!$A$1:$E$1280,5,FALSE) -> YA | I15: =VLOOKUP(C15,'Olah Data'!$B$2:$D$81,3,FALSE) -> https://kemenkeu-my.sharepoint.com/personal/izdhihar_rayhanah_kemenkeu_go_id/Documents/Apps/Microsoft%20Forms/Monitoring%20Aktivasi%20Akun%20WP%20dan%20Registrasi%20Kode%20Ot/Question/WhatsApp%20Image%202025-12-02%20at%2008.56.05_6dd328a_Duana%20Pahlawan.jpg
A16: 15 | B16: Fakhrunnisa | C16: 199410252018012003 | D16: II/d | E16: Subbagian Kepegawaian | F16: Bagian Umum | G16: =VLOOKUP(C16,'Zip Pajak'!$A$2:$E$1280,4,FALSE) -> YA | H16: =VLOOKUP(C16,'Zip Pajak'!$A$1:$E$1280,5,FALSE) -> YA | I16: =VLOOKUP(C16,'Olah Data'!$B$2:$D$81,3,FALSE) -> https://kemenkeu-my.sharepoint.com/personal/izdhihar_rayhanah_kemenkeu_go_id/Documents/Apps/Microsoft%20Forms/Monitoring%20Aktivasi%20Akun%20WP%20dan%20Registrasi%20Kode%20Ot/Question/WhatsApp%20Image%202025-12-03%20at%2014.41.15_Fakhrunnisa.jpeg
A17: 16 | B17: Izdhihar Rayhanah | C17: 199604112015122001 | D17: II/d | E17: Subbagian Kepegawaian | F17: Bagian Umum | G17: =VLOOKUP(C17,'Zip Pajak'!$A$2:$E$1280,4,FALSE) -> YA | H17: =VLOOKUP(C17,'Zip Pajak'!$A$1:$E$1280,5,FALSE) -> YA | I17: =VLOOKUP(C17,'Olah Data'!$B$2:$D$81,3,FALSE) -> https://kemenkeu-my.sharepoint.com/personal/izdhihar_rayhanah_kemenkeu_go_id/Documents/Apps/Microsoft%20Forms/Monitoring%20Aktivasi%20Akun%20WP%20dan%20Registrasi%20Kode%20Ot/Question/Screenshot%202025-12-01%20161137_Izdhihar%20Rayhanah.png
A18: 17 | B18: Achmad Safar Hidayat | C18: 199507032015021001 | D18: II/c | E18: Subbagian Rumah Tangga | F18: Bagian Umum | G18: =VLOOKUP(C18,'Zip Pajak'!$A$2:$E$1280,4,FALSE) -> YA | H18: =VLOOKUP(C18,'Zip Pajak'!$A$1:$E$1280,5,FALSE) -> BELUM KODE OTORISASI | I18: =VLOOKUP(C18,'Olah Data'!$B$2:$D$81,3,FALSE) -> https://kemenkeu-my.sharepoint.com/personal/izdhihar_rayhanah_kemenkeu_go_id/Documents/Apps/Microsoft%20Forms/Monitoring%20Aktivasi%20Akun%20WP%20dan%20Registrasi%20Kode%20Ot/Question/Screenshot%202025-12-04%20142236_Achmad%20Safar%20Hidayat.png
A19: 18 | B19: Bagus Septana Zuman Prabowo | C19: 199509032015021005 | D19: II/c | E19: Subbagian Rumah Tangga | F19: Bagian Umum | G19: =VLOOKUP(C19,'Zip Pajak'!$A$2:$E$1280,4,FALSE) -> YA | H19: =VLOOKUP(C19,'Zip Pajak'!$A$1:$E$1280,5,FALSE) -> YA | I19: =VLOOKUP(C19,'Olah Data'!$B$2:$D$81,3,FALSE) -> https://kemenkeu-my.sharepoint.com/personal/izdhihar_rayhanah_kemenkeu_go_id/Documents/Apps/Microsoft%20Forms/Monitoring%20Aktivasi%20Akun%20WP%20dan%20Registrasi%20Kode%20Ot/Question/SS%20NIE_Bagus%20Septana%20Zuman.png
... A27: 26 | B27: Mercia Widyasari | C27: 200007102019122002 | D27: II/b | E27: Subbagian Tata Usaha dan Keuangan | F27: Bagian Umum | G27: =VLOOKUP(C27,'Zip Pajak'!$A$2:$E$1280,4,FALSE) -> YA | H27: =VLOOKUP(C27,'Zip Pajak'!$A$1:$E$1280,5,FALSE) -> YA | I27: =VLOOKUP(C27,'Olah Data'!$B$2:$D$81,3,FALSE) -> https://kemenkeu-my.sharepoint.com/personal/izdhihar_rayhanah_kemenkeu_go_id/Documents/Apps/Microsoft%20Forms/Monitoring%20Aktivasi%20Akun%20WP%20dan%20Registrasi%20Kode%20Ot/Question/Nomor%20Identifikasi%20Eksternal_Mercia%20Widyasari.png
A28: 27 | B28: Bagus Sulistijono | C28: 196904151989121001 | D28: IV/b | F28: Bidang Fasilitas Kepabeanan dan Cukai | G28: =VLOOKUP(C28,'Zip Pajak'!$A$2:$E$1280,4,FALSE) -> YA | H28: =VLOOKUP(C28,'Zip Pajak'!$A$1:$E$1280,5,FALSE) -> YA | I28: =VLOOKUP(C28,'Olah Data'!$B$2:$D$81,3,FALSE) -> https://kemenkeu-my.sharepoint.com/personal/izdhihar_rayhanah_kemenkeu_go_id/Documents/Apps/Microsoft%20Forms/Monitoring%20Aktivasi%20Akun%20WP%20dan%20Registrasi%20Kode%20Ot/Question/WhatsApp%20Image%202025-12-08%20at%202.07.46%20PM_Wardah%20Nurjanah.jpeg
A29: 28 | B29: Muladi Seno | C29: 196905181989121002 | D29: IV/a | E29: Seksi Perijinan dan Fasilitas I | F29: Bidang Fasilitas Kepabeanan dan Cukai | G29: =VLOOKUP(C29,'Zip Pajak'!$A$2:$E$1280,4,FALSE) -> TIDAK | H29: =VLOOKUP(C29,'Zip Pajak'!$A$1:$E$1280,5,FALSE) -> BELUM KODE OTORISASI | I29: =VLOOKUP(C29,'Olah Data'!$B$2:$D$81,3,FALSE) -> https://kemenkeu-my.sharepoint.com/personal/izdhihar_rayhanah_kemenkeu_go_id/Documents/Apps/Microsoft%20Forms/Monitoring%20Aktivasi%20Akun%20WP%20dan%20Registrasi%20Kode%20Ot/Question/Screenshot%202025-12-08%20135452_Wekalaili%20Fadhila.png
A30: 29 | B30: Niken Lestrie Premanawatie | C30: 197007071990122001 | D30: IV/a | E30: Seksi Bimbingan Kepatuhan dan Hubungan Masyarakat | F30: Bidang Fasilitas Kepabeanan dan Cukai | G30: =VLOOKUP(C30,'Zip Pajak'!$A$2:$E$1280,4,FALSE) -> YA | H30: =VLOOKUP(C30,'Zip Pajak'!$A$1:$E$1280,5,FALSE) -> YA | I30: =VLOOKUP(C30,'Olah Data'!$B$2:$D$81,3,FALSE) -> https://kemenkeu-my.sharepoint.com/personal/izdhihar_rayhanah_kemenkeu_go_id/Documents/Apps/Microsoft%20Forms/Monitoring%20Aktivasi%20Akun%20WP%20dan%20Registrasi%20Kode%20Ot/Question/5eaaf926-f097-4f16-87cb-d67cfd53af58_Niken%20Premanawatie.jpeg
A31: 30 | B31: Erna Rahayu | C31: 197201021992012001 | D31: III/d | E31: Seksi Perijinan dan Fasilitas III | F31: Bidang Fasilitas Kepabeanan dan Cukai | G31: =VLOOKUP(C31,'Zip Pajak'!$A$2:$E$1280,4,FALSE) -> YA | H31: =VLOOKUP(C31,'Zip Pajak'!$A$1:$E$1280,5,FALSE) -> YA | I31: =VLOOKUP(C31,'Olah Data'!$B$2:$D$81,3,FALSE) -> #N/A
A32: 31 | B32: Farid Hendriyanto | C32: 197509082005011001 | D32: III/d | E32: Seksi Perijinan dan Fasilitas II | F32: Bidang Fasilitas Kepabeanan dan Cukai | G32: =VLOOKUP(C32,'Zip Pajak'!$A$2:$E$1280,4,FALSE) -> TIDAK | H32: =VLOOKUP(C32,'Zip Pajak'!$A$1:$E$1280,5,FALSE) -> BELUM KODE OTORISASI | I32: =VLOOKUP(C32,'Olah Data'!$B$2:$D$81,3,FALSE) -> #N/A
A33: 32 | B33: Romdloni | C33: 197208111992121001 | D33: III/d | E33: Seksi Perijinan dan Fasilitas II | F33: Bidang Fasilitas Kepabeanan dan Cukai | G33: =VLOOKUP(C33,'Zip Pajak'!$A$2:$E$1280,4,FALSE) -> YA | H33: =VLOOKUP(C33,'Zip Pajak'!$A$1:$E$1280,5,FALSE) -> YA | I33: =VLOOKUP(C33,'Olah Data'!$B$2:$D$81,3,FALSE) -> https://kemenkeu-my.sharepoint.com/personal/izdhihar_rayhanah_kemenkeu_go_id/Documents/Apps/Microsoft%20Forms/Monitoring%20Aktivasi%20Akun%20WP%20dan%20Registrasi%20Kode%20Ot/Question/Bukti%20Registrasi%20Kode%20Otorisasi_Romdloni%20-.PNG
A34: 33 | B34: Seliana Happira | C34: 197910232003122002 | D34: III/d | E34: Seksi Perijinan dan Fasilitas I | F34: Bidang Fasilitas Kepabeanan dan Cukai | G34: =VLOOKUP(C34,'Zip Pajak'!$A$2:$E$1280,4,FALSE) -> TIDAK | H34: =VLOOKUP(C34,'Zip Pajak'!$A$1:$E$1280,5,FALSE) -> BELUM KODE OTORISASI | I34: =VLOOKUP(C34,'Olah Data'!$B$2:$D$81,3,FALSE) -> https://kemenkeu-my.sharepoint.com/personal/izdhihar_rayhanah_kemenkeu_go_id/Documents/Apps/Microsoft%20Forms/Monitoring%20Aktivasi%20Akun%20WP%20dan%20Registrasi%20Kode%20Ot/Question/Bukti%20Kode%20Otorisasi%20DJP%20Seli_Seliana%20Happira,%20A.M.png
A35: 34 | B35: Dedy Kurniawan | C35: 198705102010121003 | D35: III/b | E35: Seksi Perijinan dan Fasilitas I | F35: Bidang Fasilitas Kepabeanan dan Cukai | G35: =VLOOKUP(C35,'Zip Pajak'!$A$2:$E$1280,4,FALSE) -> YA | H35: =VLOOKUP(C35,'Zip Pajak'!$A$1:$E$1280,5,FALSE) -> YA | I35: =VLOOKUP(C35,'Olah Data'!$B$2:$D$81,3,FALSE) -> #N/A
A36: 35 | B36: Rahma Abi Syaid | C36: 199407272018011005 | D36: III/b | E36: Seksi Perijinan dan Fasilitas III | F36: Bidang Fasilitas Kepabeanan dan Cukai | G36: =VLOOKUP(C36,'Zip Pajak'!$A$2:$E$1280,4,FALSE) -> YA | H36: =VLOOKUP(C36,'Zip Pajak'!$A$1:$E$1280,5,FALSE) -> YA | I36: =VLOOKUP(C36,'Olah Data'!$B$2:$D$81,3,FALSE) -> #N/A
A37: 36 | B37: Tatik Apriati | C37: 199104232018012003 | D37: III/b | E37: Seksi Perijinan dan Fasilitas I | F37: Bidang Fasilitas Kepabeanan dan Cukai | G37: =VLOOKUP(C37,'Zip Pajak'!$A$2:$E$1280,4,FALSE) -> YA | H37: =VLOOKUP(C37,'Zip Pajak'!$A$1:$E$1280,5,FALSE) -> YA | I37: =VLOOKUP(C37,'Olah Data'!$B$2:$D$81,3,FALSE) -> #N/A
A38: 37 | B38: Dhony Prasetyo Utomo | C38: 198904082010011002 | D38: III/a | E38: Seksi Bimbingan Kepatuhan dan Hubungan Masyarakat | F38: Bidang Fasilitas Kepabeanan dan Cukai | G38: =VLOOKUP(C38,'Zip Pajak'!$A$2:$E$1280,4,FALSE) -> YA | H38: =VLOOKUP(C38,'Zip Pajak'!$A$1:$E$1280,5,FALSE) -> YA | I38: =VLOOKUP(C38,'Olah Data'!$B$2:$D$81,3,FALSE) -> https://kemenkeu-my.sharepoint.com/personal/izdhihar_rayhanah_kemenkeu_go_id/Documents/Apps/Microsoft%20Forms/Monitoring%20Aktivasi%20Akun%20WP%20dan%20Registrasi%20Kode%20Ot/Question/Kode%20Otorisasi%20-%20Dhony_Dhony%20Prasetyo%20Utomo.png
A39: 38 | B39: Dilla Kusuma Wardhani | C39: 199503112018012001 | D39: III/a | E39: Seksi Perijinan dan Fasilitas III | F39: Bidang Fasilitas Kepabeanan dan Cukai | G39: =VLOOKUP(C39,'Zip Pajak'!$A$2:$E$1280,4,FALSE) -> YA | H39: =VLOOKUP(C39,'Zip Pajak'!$A$1:$E$1280,5,FALSE) -> YA | I39: =VLOOKUP(C39,'Olah Data'!$B$2:$D$81,3,FALSE) -> #N/A
A40: 39 | B40: Reza Amir Muzaki | C40: 199110042014111001 | D40: III/a | E40: Seksi Perijinan dan Fasilitas II | F40: Bidang Fasilitas Kepabeanan dan Cukai | G40: =VLOOKUP(C40,'Zip Pajak'!$A$2:$E$1280,4,FALSE) -> YA | H40: =VLOOKUP(C40,'Zip Pajak'!$A$1:$E$1280,5,FALSE) -> YA | I40: =VLOOKUP(C40,'Olah Data'!$B$2:$D$81,3,FALSE) -> #N/A
... A48: 47 | B48: Wekalaili Fadhila | C48: 199804252018012001 | D48: II/b | E48: Seksi Perijinan dan Fasilitas I | F48: Bidang Fasilitas Kepabeanan dan Cukai | G48: =VLOOKUP(C48,'Zip Pajak'!$A$2:$E$1280,4,FALSE) -> YA | H48: =VLOOKUP(C48,'Zip Pajak'!$A$1:$E$1280,5,FALSE) -> YA | I48: =VLOOKUP(C48,'Olah Data'!$B$2:$D$81,3,FALSE) -> https://kemenkeu-my.sharepoint.com/personal/izdhihar_rayhanah_kemenkeu_go_id/Documents/Apps/Microsoft%20Forms/Monitoring%20Aktivasi%20Akun%20WP%20dan%20Registrasi%20Kode%20Ot/Question/Screenshot%202025-12-08%20111757_Wekalaili%20Fadhila.png
A49: 48 | B49: Kunawi | C49: 196907171996031001 | D49: IV/b | F49: Bidang Kepabeanan dan Cukai | G49: =VLOOKUP(C49,'Zip Pajak'!$A$2:$E$1280,4,FALSE) -> TIDAK | H49: =VLOOKUP(C49,'Zip Pajak'!$A$1:$E$1280,5,FALSE) -> BELUM KODE OTORISASI | I49: =VLOOKUP(C49,'Olah Data'!$B$2:$D$81,3,FALSE) -> #N/A
A50: 49 | B50: Ahmad Saiful Mustofa | C50: 197808142001121001 | D50: III/d | E50: Seksi Penerimaan dan Pengelolaan Data | F50: Bidang Kepabeanan dan Cukai | G50: =VLOOKUP(C50,'Zip Pajak'!$A$2:$E$1280,4,FALSE) -> YA | H50: =VLOOKUP(C50,'Zip Pajak'!$A$1:$E$1280,5,FALSE) -> YA | I50: =VLOOKUP(C50,'Olah Data'!$B$2:$D$81,3,FALSE) -> #N/A
A51: 50 | B51: Djoko Slamet | C51: 197504201997031002 | D51: III/d | E51: Seksi Pemeriksaan | F51: Bidang Kepabeanan dan Cukai | G51: =VLOOKUP(C51,'Zip Pajak'!$A$2:$E$1280,4,FALSE) -> YA | H51: =VLOOKUP(C51,'Zip Pajak'!$A$1:$E$1280,5,FALSE) -> YA | I51: =VLOOKUP(C51,'Olah Data'!$B$2:$D$81,3,FALSE) -> https://kemenkeu-my.sharepoint.com/personal/izdhihar_rayhanah_kemenkeu_go_id/_layouts/15/Doc.aspx?sourcedoc=%7B51AEAEAD-1DB0-4F85-B9B1-25CB06BA109B%7D&file=SS%20Coretax_Djoko%20Slamet,%20S.E..docx&action=default&mobileredirect=true
A52: 51 | B52: Dyah Ayu Resti Nugraheni | C52: 198701192010122006 | D52: III/d | E52: Seksi Pemeriksaan | F52: Bidang Kepabeanan dan Cukai | G52: =VLOOKUP(C52,'Zip Pajak'!$A$2:$E$1280,4,FALSE) -> YA | H52: =VLOOKUP(C52,'Zip Pajak'!$A$1:$E$1280,5,FALSE) -> YA | I52: =VLOOKUP(C52,'Olah Data'!$B$2:$D$81,3,FALSE) -> https://kemenkeu-my.sharepoint.com/personal/izdhihar_rayhanah_kemenkeu_go_id/Documents/Apps/Microsoft%20Forms/Monitoring%20Aktivasi%20Akun%20WP%20dan%20Registrasi%20Kode%20Ot/Question/Bukti%20Registrasi%20Otorisasi%20Coretax_Dyah%20Ayu%20R_Dyah%20Ayu%20Resti%20Nugra.jpeg
A53: 52 | B53: Heru Wahyudi | C53: 197904072000121001 | D53: III/d | E53: Seksi Pemeriksaan | F53: Bidang Kepabeanan dan Cukai | G53: =VLOOKUP(C53,'Zip Pajak'!$A$2:$E$1280,4,FALSE) -> TIDAK | H53: =VLOOKUP(C53,'Zip Pajak'!$A$1:$E$1280,5,FALSE) -> BELUM KODE OTORISASI | I53: =VLOOKUP(C53,'Olah Data'!$B$2:$D$81,3,FALSE) -> #N/A
A54: 53 | B54: Mahmud Zein Firmansyah | C54: 198405202009011010 | D54: III/d | E54: Seksi Bantuan Hukum | F54: Bidang Kepabeanan dan Cukai | G54: =VLOOKUP(C54,'Zip Pajak'!$A$2:$E$1280,4,FALSE) -> TIDAK | H54: =VLOOKUP(C54,'Zip Pajak'!$A$1:$E$1280,5,FALSE) -> BELUM KODE OTORISASI | I54: =VLOOKUP(C54,'Olah Data'!$B$2:$D$81,3,FALSE) -> https://kemenkeu-my.sharepoint.com/personal/izdhihar_rayhanah_kemenkeu_go_id/Documents/Apps/Microsoft%20Forms/Monitoring%20Aktivasi%20Akun%20WP%20dan%20Registrasi%20Kode%20Ot/Question/bukti%20otorisasi%20Pajak%20Core%20tax_Mahmud%20Zein%20Firmansy.jpg
...

Sheet Daftar Pegawai
A1: No | B1: Nama Pegawai | C1: NIP | D1: Pangkat | E1: Jabatan | F1: Unit Organisasi
A2: 1 | B2: A. A. Ngurah Agung Kamasan | C2: 199009252010011002 | D2: Penata Muda-III/a | E2: Pemeriksa Bea Dan Cukai Pelaksana Pada Kantor Pengawasan Dan Pelayanan Bea Dan Cukai Tipe Madya Pabean Juanda, Kantor Wilayah Direktorat Jenderal Bea Dan Cukai Jawa Timur I | F2: Kantor Pengawasan dan Pelayanan Bea dan Cukai Tipe Madya Pabean Juanda, Kantor Wilayah Direktorat Jenderal Bea dan Cukai Jawa Timur I
A3: 2 | B3: A. Makmuridin | C3: 197903142000121002 | D3: Penata Tk.I-III/d | E3: Pemeriksa Bea Dan Cukai Muda Pada Kantor Pengawasan Dan Pelayanan Bea Dan Cukai Tipe Madya Pabean Tanjung Perak, Kantor Wilayah Direktorat Jenderal Bea Dan Cukai Jawa Timur I | F3: Kantor Pengawasan dan Pelayanan Bea dan Cukai Tipe Madya Pabean Tanjung Perak, Kantor Wilayah Direktorat Jenderal Bea dan Cukai Jawa Timur I
A4: 3 | B4: A. Misbahul Huda | C4: 199411212015021002 | D4: Pengatur-II/c | E4: Pemeriksa Bea Dan Cukai Pelaksana Pada Kantor Pengawasan Dan Pelayanan Bea Dan Cukai Tipe Madya Pabean Tanjung Perak, Kantor Wilayah Direktorat Jenderal Bea Dan Cukai Jawa Timur I | F4: Kantor Pengawasan dan Pelayanan Bea dan Cukai Tipe Madya Pabean Tanjung Perak, Kantor Wilayah Direktorat Jenderal Bea dan Cukai Jawa Timur I
A5: 4 | B5: Aang Sudrajat | C5: 199102242009121001 | D5: Penata Muda-III/a | E5: Pemeriksa Bea Dan Cukai Pelaksana Pada Kantor Pengawasan Dan Pelayanan Bea Dan Cukai Tipe Madya Pabean Tanjung Perak, Kantor Wilayah Direktorat Jenderal Bea Dan Cukai Jawa Timur I | F5: Kantor Pengawasan dan Pelayanan Bea dan Cukai Tipe Madya Pabean Tanjung Perak, Kantor Wilayah Direktorat Jenderal Bea dan Cukai Jawa Timur I
A6: 5 | B6: Abdul Abas Nur Aprianto | C6: 199304032013101002 | D6: Pengatur Tk. I-II/d | E6: Pelaksana Pemeriksa Pada Subbagian Umum, Kantor Pengawasan Dan Pelayanan Bea Dan Cukai Tipe Madya Pabean A Pasuruan, Kantor Wilayah Direktorat Jenderal Bea Dan Cukai Jawa Timur I | F6: Subbagian Umum, Kantor Pengawasan dan Pelayanan Bea dan Cukai Tipe Madya Pabean A Pasuruan, Kantor Wilayah Direktorat Jenderal Bea dan Cukai Jawa Timur I
A7: 6 | B7: Abdul Azis Nurrahman Febrianto | C7: 199702162016121001 | D7: Pengatur-II/c | E7: Pelaksana Pemeriksa Pada Seksi Pengolahan Data Dan Administrasi Dokumen, Kantor Pengawasan Dan Pelayanan Bea Dan Cukai Tipe Madya Pabean Tanjung Perak, Kantor Wilayah Direktorat Jenderal Bea Dan Cukai Jawa Timur I | F7: Seksi Pengolahan Data dan Administrasi Dokumen, Kantor Pengawasan dan Pelayanan Bea dan Cukai Tipe Madya Pabean Tanjung Perak, Kantor Wilayah Direktorat Jenderal Bea dan Cukai Jawa Timur I
A8: 7 | B8: Abdul Majid Riyadu Sholichin | C8: 199209232012101002 | D8: Penata Muda-III/a | E8: Pemeriksa Bea Dan Cukai Pelaksana Lanjutan Pada Kantor Wilayah Direktorat Jenderal Bea Dan Cukai Jawa Timur I | F8: Kantor Wilayah Direktorat Jenderal Bea dan Cukai Jawa Timur I
A9: 8 | B9: Abdul Malik Zulkarnain | C9: 198711032007011003 | D9: Penata Muda Tk.I-III/b | E9: Pemeriksa Bea Dan Cukai Pertama Pada Kantor Pengawasan Dan Pelayanan Bea Dan Cukai Tipe Madya Pabean Juanda, Kantor Wilayah Direktorat Jenderal Bea Dan Cukai Jawa Timur I | F9: Kantor Pengawasan dan Pelayanan Bea dan Cukai Tipe Madya Pabean Juanda, Kantor Wilayah Direktorat Jenderal Bea dan Cukai Jawa Timur I
A10: 9 | B10: Abdul Rochim | C10: 199005232009121001 | D10: Pengatur Tk. I-II/d | E10: Pelaksana Pemeriksa Pada Seksi Pelayanan Kepabeanan Dan Cukai I, Kantor Pengawasan Dan Pelayanan Bea Dan Cukai Tipe Madya Pabean B Gresik, Kantor Wilayah Direktorat Jenderal Bea Dan Cukai Jawa Timur I | F10: Seksi Pelayanan Kepabeanan dan Cukai I, Kantor Pengawasan dan Pelayanan Bea dan Cukai Tipe Madya Pabean B Gresik, Kantor Wilayah Direktorat Jenderal Bea dan Cukai Jawa Timur I
A11: 10 | B11: Abdulrahman Wahid | C11: 199101252009121002 | D11: Pengatur Tk. I-II/d | E11: Pelaksana Pemeriksa Pada Seksi Pelayanan Kepabeanan Dan Cukai Ii, Kantor Pengawasan Dan Pelayanan Bea Dan Cukai Tipe Madya Pabean B Gresik, Kantor Wilayah Direktorat Jenderal Bea Dan Cukai Jawa Timur I | F11: Seksi Pelayanan Kepabeanan dan Cukai II, Kantor Pengawasan dan Pelayanan Bea dan Cukai Tipe Madya Pabean B Gresik, Kantor Wilayah Direktorat Jenderal Bea dan Cukai Jawa Timur I
A12: 11 | B12: Abhista Lalang Dewangga Hendyka | C12: 200008182019121001 | D12: Pengatur Muda Tk. I-II/b | E12: Pelaksana Pemeriksa Pada Seksi Penindakan Dan Penyidikan, Kantor Pengawasan Dan Pelayanan Bea Dan Cukai Tipe Madya Pabean Tanjung Perak, Kantor Wilayah Direktorat Jenderal Bea Dan Cukai Jawa Timur I | F12: Seksi Penindakan dan Penyidikan, Kantor Pengawasan dan Pelayanan Bea dan Cukai Tipe Madya Pabean Tanjung Perak, Kantor Wilayah Direktorat Jenderal Bea dan Cukai Jawa Timur I
A13: 12 | B13: Abi Aswanata Utama | C13: 199211062012101003 | D13: Pengatur Tk. I-II/d | E13: Pelaksana Pemeriksa Pada Seksi Kepatuhan Internal Dan Penyuluhan, Kantor Pengawasan Dan Pelayanan Bea Dan Cukai Tipe Madya Pabean C Madura, Kantor Wilayah Direktorat Jenderal Bea Dan Cukai Jawa Timur I | F13: Seksi Kepatuhan Internal dan Penyuluhan, Kantor Pengawasan dan Pelayanan Bea dan Cukai Tipe Madya Pabean C Madura, Kantor Wilayah Direktorat Jenderal Bea dan Cukai Jawa Timur I
... A1297: 1296 | B1297: Zuqri Rieka Mahanani | C1297: 199901012018012001 | D1297: Pengatur Muda Tk. I-II/b | E1297: Pelaksana Pemeriksa Pada Seksi Penindakan I, Bidang Penindakan Dan Penyidikan, Kantor Wilayah Direktorat Jenderal Bea Dan Cukai Jawa Timur I | F1297: Seksi Penindakan I, Bidang Penindakan dan Penyidikan, Kantor Wilayah Direktorat Jenderal Bea dan Cukai Jawa Timur I

Sheet Zip Pajak
A1: NIP | B1: NAMA | C1: NPWP16 | D1: LOGIN_PORTAL (SUDAH PERNAH LOG IN) | E1: SUDAH KODE OTORISASI / BELUM
A2: 197003131989121001 | B2: Himawan Indarjono | C2: 3174061303700001 | D2: YA | E2: YA
A3: 197504281996021001 | B3: Sapta Pinardi | C3: 3515162804750004 | D3: YA | E3: YA
A4: 197611232002121001 | B4: Angga Girasandi Argadinata | C4: 3276022311760006 | D4: YA | E4: YA
A5: 197706241997031002 | B5: Bambang Subeqi | C5: 3515162406770002 | D5: TIDAK | E5: BELUM KODE OTORISASI
A6: 197911102001121001 | B6: Ahmad Saifuddin Zuhri | C6: 3515171011790001 | D6: YA | E6: YA
A7: 198111182003122007 | B7: Fenti Fitria Lestari | C7: 3515165811810006 | D7: YA | E7: YA
A8: 198707052006021002 | B8: Mudho Cahyo Utomo | C8: 3175020507870006 | D8: YA | E8: YA
A9: 199003012012102002 | B9: Dwi Sriwahyuni | C9: 3510062804880005 | D9: YA | E9: YA
A10: 199005232012102001 | B10: Meriana Dwi Puspita | C10: 3510062303880002 | D10: YA | E10: YA
A11: 199304062013101001 | B11: Kresnawan Dwi Aprianto | C11: 3578040604930002 | D11: TIDAK | E11: BELUM KODE OTORISASI
A12: 199407212015021002 | B12: Hendy Dody Nugroho | C12: 3518062107940003 | D12: YA | E12: YA
... A1280: 200101082019122002 | B1280: Nasa Pradnyaparamita | C1280: 3401074801010004 | D1280: TIDAK | E1280: BELUM KODE OTORISASI

Sheet Olah Data
A1: Nama | B1: NIP | C1: Unit | D1: Bukti Registrasi Kode Otorisasi (contoh terlampir)
A2: Izdhihar Rayhanah | B2: 199604112015122001 | C2: Bagian Umum (termasuk fungsional APBN) | D2: https://kemenkeu-my.sharepoint.com/personal/izdhihar_rayhanah_kemenkeu_go_id/Documents/Apps/Microsoft%20Forms/Monitoring%20Aktivasi%20Akun%20WP%20dan%20Registrasi%20Kode%20Ot/Question/Screenshot%202025-12-01%20161137_Izdhihar%20Rayhanah.png
A3: Bella Atria | B3: 199701312015122001 | C3: Bagian Umum (termasuk fungsional APBN) | D3: https://kemenkeu-my.sharepoint.com/personal/izdhihar_rayhanah_kemenkeu_go_id/Documents/Apps/Microsoft%20Forms/Monitoring%20Aktivasi%20Akun%20WP%20dan%20Registrasi%20Kode%20Ot/Question/Bukti%20kode%20otorisasi_Bella%20Atria.png
A4: Duana Jerry Pahlawan | B4: 199611102018121002 | C4: Bagian Umum (termasuk fungsional APBN) | D4: https://kemenkeu-my.sharepoint.com/personal/izdhihar_rayhanah_kemenkeu_go_id/Documents/Apps/Microsoft%20Forms/Monitoring%20Aktivasi%20Akun%20WP%20dan%20Registrasi%20Kode%20Ot/Question/WhatsApp%20Image%202025-12-02%20at%2008.56.05_6dd328a_Duana%20Pahlawan.jpg
A5: Muhammad Rizal Arfan Afiat | B5: 199901302018121003 | C5: Bagian Umum (termasuk fungsional APBN) | D5: https://kemenkeu-my.sharepoint.com/personal/izdhihar_rayhanah_kemenkeu_go_id/Documents/Apps/Microsoft%20Forms/Monitoring%20Aktivasi%20Akun%20WP%20dan%20Registrasi%20Kode%20Ot/Question/Screenshot%202025-12-02%20095813_Rizal%20Afiat.png
A6: Ayunanda Melliana | B6: 199010142014022005 | C6: Bidang Penindakan dan Penyidikan | D6: https://kemenkeu-my.sharepoint.com/personal/izdhihar_rayhanah_kemenkeu_go_id/Documents/Apps/Microsoft%20Forms/Monitoring%20Aktivasi%20Akun%20WP%20dan%20Registrasi%20Kode%20Ot/Question/Bukti%201_Ayunanda%20Melliana.pdf
A7: Kiflan Aria Yudha | B7: 199907202018121001 | C7: Bagian Umum (termasuk fungsional APBN) | D7: https://kemenkeu-my.sharepoint.com/personal/izdhihar_rayhanah_kemenkeu_go_id/Documents/Apps/Microsoft%20Forms/Monitoring%20Aktivasi%20Akun%20WP%20dan%20Registrasi%20Kode%20Ot/Question/Bukti%20Aktivasi%20Coretax_Kiflan%20Aria%20Yudha.pdf
A8: Wahyudin Halim | B8: 198205162002121006 | C8: Fungsional Audit | D8: https://kemenkeu-my.sharepoint.com/personal/izdhihar_rayhanah_kemenkeu_go_id/Documents/Apps/Microsoft%20Forms/Monitoring%20Aktivasi%20Akun%20WP%20dan%20Registrasi%20Kode%20Ot/Question/Coretax%20Wahyudin%20Halim_Wahyudin%20Halim.pdf
A9: Pande Putu Anindia Yadnya Pratama R. | B9: 199305152012101001 | C9: Bidang Kepatuhan Internal | D9: https://kemenkeu-my.sharepoint.com/personal/izdhihar_rayhanah_kemenkeu_go_id/Documents/Apps/Microsoft%20Forms/Monitoring%20Aktivasi%20Akun%20WP%20dan%20Registrasi%20Kode%20Ot/Question/Bukti%20Sudah%20Mendapatkan%20Valid%20Kode%20Eksternal_Pande%20Putu%20Anindia%20Y.png
A10: Mohammad Muqorrobin | B10: 199205282014111003 | C10: Bidang Kepabeanan dan Cukai | D10: https://kemenkeu-my.sharepoint.com/personal/izdhihar_rayhanah_kemenkeu_go_id/Documents/Apps/Microsoft%20Forms/Monitoring%20Aktivasi%20Akun%20WP%20dan%20Registrasi%20Kode%20Ot/Question/CORETAX%20MOHAMMAD%20MUQORROBIN_Mohammad%20Muqorrobin.png
A11: Debby Cheilasari | B11: 199608082015122003 | C11: Bidang Kepatuhan Internal | D11: https://kemenkeu-my.sharepoint.com/personal/izdhihar_rayhanah_kemenkeu_go_id/Documents/Apps/Microsoft%20Forms/Monitoring%20Aktivasi%20Akun%20WP%20dan%20Registrasi%20Kode%20Ot/Question/Screenshot%202025-12-02%20113120_Debby%20Cheilasari.png
A12: Wira Putri Munita | B12: 199907312018122001 | C12: Bidang Kepatuhan Internal | D12: https://kemenkeu-my.sharepoint.com/personal/izdhihar_rayhanah_kemenkeu_go_id/Documents/Apps/Microsoft%20Forms/Monitoring%20Aktivasi%20Akun%20WP%20dan%20Registrasi%20Kode%20Ot/Question/WhatsApp%20Image%202025-12-02%20at%2011.44.19_Wira%20Putri%20Munita.jpeg
... A81: I Gde Hanggara Hermawan | B81: 198412182006021003 | C81: Fungsional Keberatan dan Banding | D81: https://kemenkeu-my.sharepoint.com/personal/izdhihar_rayhanah_kemenkeu_go_id/_layouts/15/Doc.aspx?sourcedoc=%7BE9F01525-F67B-4A98-8D47-6F510AA0C96B%7D&file=aktivasi%20e%20tax%20court%20-%20I%20Gde%20Hanggara%20Hermawa_I%20GDE%20HANGGARA%20HERMA.docx&action=default&mobileredirect=true
